Workbook

Sheet Literature summary
B1: The list | D1: Ingestion (text into the vault) | G1: Synthesis
A2: Area | B2: Sources | C2: Acquired | D2: Ingested | E2: % of sources | F2: Needs attention | G2: Synthesized | H2: % of sources
A3: Economic Activity | B3: =COUNTA('Qual - Economic Activity'!A:A)-1-COUNTIF('Qual - Economic Activity'!E:E,"Dropped") | C3: =COUNTIF('Qual - Economic Activity'!E:E,"Yes") | D3: =COUNTIF('Qual - Economic Activity'!K:K,"Ingested") | E3: =IF(B3=0,"",D3/B3) | F3: =COUNTIF('Qual - Economic Activity'!K:K,"Needs attention") | G3: =COUNTIF('Qual - Economic Activity'!O:O,"Yes") | H3: =IF(B3=0,"",G3/B3)
A4: Exchange Rate | B4: =COUNTA('Qual - Exchange Rate'!A:A)-1-COUNTIF('Qual - Exchange Rate'!E:E,"Dropped") | C4: =COUNTIF('Qual - Exchange Rate'!E:E,"Yes") | D4: =COUNTIF('Qual - Exchange Rate'!K:K,"Ingested") | E4: =IF(B4=0,"",D4/B4) | F4: =COUNTIF('Qual - Exchange Rate'!K:K,"Needs attention") | G4: =COUNTIF('Qual - Exchange Rate'!O:O,"Yes") | H4: =IF(B4=0,"",G4/B4)
A5: Fiscal Policy | B5: =COUNTA('Qual - Fiscal Policy'!A:A)-1-COUNTIF('Qual - Fiscal Policy'!E:E,"Dropped") | C5: =COUNTIF('Qual - Fiscal Policy'!E:E,"Yes") | D5: =COUNTIF('Qual - Fiscal Policy'!K:K,"Ingested") | E5: =IF(B5=0,"",D5/B5) | F5: =COUNTIF('Qual - Fiscal Policy'!K:K,"Needs attention") | G5: =COUNTIF('Qual - Fiscal Policy'!O:O,"Yes") | H5: =IF(B5=0,"",G5/B5)
A6: Inflation | B6: =COUNTA('Qual - Inflation'!A:A)-1-COUNTIF('Qual - Inflation'!E:E,"Dropped") | C6: =COUNTIF('Qual - Inflation'!E:E,"Yes") | D6: =COUNTIF('Qual - Inflation'!K:K,"Ingested") | E6: =IF(B6=0,"",D6/B6) | F6: =COUNTIF('Qual - Inflation'!K:K,"Needs attention") | G6: =COUNTIF('Qual - Inflation'!O:O,"Yes") | H6: =IF(B6=0,"",G6/B6)
A7: Labor Market | B7: =COUNTA('Qual - Labor Market'!A:A)-1-COUNTIF('Qual - Labor Market'!E:E,"Dropped") | C7: =COUNTIF('Qual - Labor Market'!E:E,"Yes") | D7: =COUNTIF('Qual - Labor Market'!K:K,"Ingested") | E7: =IF(B7=0,"",D7/B7) | F7: =COUNTIF('Qual - Labor Market'!K:K,"Needs attention") | G7: =COUNTIF('Qual - Labor Market'!O:O,"Yes") | H7: =IF(B7=0,"",G7/B7)
A8: Monetary Policy | B8: =COUNTA('Qual - Monetary Policy'!A:A)-1-COUNTIF('Qual - Monetary Policy'!E:E,"Dropped") | C8: =COUNTIF('Qual - Monetary Policy'!E:E,"Yes") | D8: =COUNTIF('Qual - Monetary Policy'!K:K,"Ingested") | E8: =IF(B8=0,"",D8/B8) | F8: =COUNTIF('Qual - Monetary Policy'!K:K,"Needs attention") | G8: =COUNTIF('Qual - Monetary Policy'!O:O,"Yes") | H8: =IF(B8=0,"",G8/B8)
A9: Trader | B9: =COUNTA('Qual - Trader'!A:A)-1-COUNTIF('Qual - Trader'!E:E,"Dropped") | C9: =COUNTIF('Qual - Trader'!E:E,"Yes") | D9: =COUNTIF('Qual - Trader'!K:K,"Ingested") | E9: =IF(B9=0,"",D9/B9) | F9: =COUNTIF('Qual - Trader'!K:K,"Needs attention") | G9: =COUNTIF('Qual - Trader'!O:O,"Yes") | H9: =IF(B9=0,"",G9/B9)
A10: Total | B10: =SUM(B3:B9) | C10: =SUM(C3:C9) | D10: =SUM(D3:D9) | E10: =IF(B10=0,"",D10/B10) | F10: =SUM(F3:F9) | G10: =SUM(G3:G9) | H10: =IF(B10=0,"",G10/B10)
A12: Sources: rows of the area tab, one per file (a book has a row per chapter), dropped rows excluded. Acquired: the PDF is in the folder. Ingested: its text is in the vault. Needs attention: ingestion was tried and the tools could not read it (a scan, a broken font — the reason is in the area tab). Synthesized: the ingested file has a synthesis note. Both % columns divide by Sources.
A13: Acquired but neither Ingested nor Needs attention: not run yet (/ingest), or the area is on hold in settings.yaml (Trader). Recurring BCB documents (Copom statement, minutes, RPM) reach the vault through the Copom ETL and have no row here.
A14: The reasoning behind each area's list — scope, cluster notes, open gaps, acquisition order — is in the Notes tab.
A15: Written by repository/ingestion/scripts/tracker.py on every ingestion. In the area tabs, teal columns are yours, navy ones the system's.

Sheet Notes
A1: Area | B1: Kind | C1: Cluster / section | D1: What it covers | E1: Notes
A2: Exchange Rate | B2: Literature | C2: (whole area) | D2: Scope | E2: Excluded here: #pass_through_and_inflation. That cluster sits at a genuine intersection between this exchange-rate bibliography and the inflation agent's own bibliography (the Qual - Inflation tab) — which side of that boundary owns exchange-rate pass-through hasn't been decided yet, the same kind of explicit scope call other topics in this series have had to make (e.g. fiscal policy vs. monetary policy on fiscal dominance, in the Qual - Fiscal Policy tab). Goldfajn & Werlang (2000), Belaisch (2003), and Araújo/Caldarelli/Cortapasso (2023) remain exactly where they are in exchange_rate_conceptual_map.md and repository/exchange_rate/ — only removed from this consolidated list pending that ownership decision.
A3: Exchange Rate | B3: Literature | C3: (whole area) | D3: Where the base is strong (multiple independent sources converge) | E3: - Interest-rate/exchange-rate parity conditions (UIP, CIP, real interest parity, international Fisher effect) — covered from five independent angles (CFA L1/L2, Krugman Ch. 14/16, Dornbusch, and now Fama's 1984 original econometric source) that consistently cross-reference and refine each other. This is the single best-supported cluster in the base, and now includes the actual academic origin of the "wrong-signed beta"/forward-premium-puzzle result the other sources describe narratively. - Exchange-rate pass-through, with a genuine Brazil specialization — five sources (Goldfajn 2000, Belaisch 2003, Krugman Ch. 17's Marshall-Lerner/J-curve, Cortapasso et al. 2023, and the BCB note) build a coherent, empirically-grounded, Brazil-specific picture: aggregate pass-through → distribution-chain detail → formal elasticity conditions → state-dependent/asymmetric refinement → market-plumbing detail. This is arguably the base's most distinctive strength relative to a generic textbook treatment, and directly serves LIS's Brazil macro mandate. - Fixed-rate mechanics and currency crises — now the base's deepest cluster after the 2026-07 addition of five academic crisis-model papers (sources 19-23). The operational "how a peg is actually defended, and how it breaks" story (Mundell 1963 → Krugman Ch. 18 → CFA L2's warning-sign checklist → four case studies: Malaysia, Iceland, Switzerland, Brazil 2002-2011) is now backed by the full academic theoretical spine it previously lacked: the original first-generation model and its linear/stochastic companion (Krugman 1979; Flood & Garber 1983/84), the original second-generation self-fulfilling model (Obstfeld 1984), and both major competing third-generation models (Krugman's balance-sheet/transfer-problem model, 2000; Chang & Velasco's open-economy bank-run model, 1998) — including their own direct debate with each other over which mechanism actually drove the 1997-98 Asian crisis. Includes a strong-currency defense (Switzerland), a non-crisis cautionary tale (Brazil), and now a first-hand methodological self-critique (Garber's "generational taxonomy is a name swindle" comment) — a genuinely well-rounded, non-one-note treatment of the topic. - Equilibrium/fair-value estimation (BEER/GSDEER/GSFEER) — the two major methodological families (academic BEER, practitioner GSDEER, and now GSFEER) are all present with enough detail to compare their assumptions, failure modes, and current live signals for BRL specifically. - Capital controls as a policy tool — no longer a single-source cluster after the 2026-07 addition of both the empirical precursor (Ostry et al., 2010) and the IMF's own official institutional doctrine (2012 Board paper). Together with the case-study material already in #currency_crisis_dynamics/#balance_of_payments, the base now covers the full arc: when controls are justified (four-condition test), how effective they actually are (composition vs. volume effects, the 2008-09 natural experiment), the CFM/MPM terminology distinction, liberalization sequencing, and the multilateral-spillover case against unilateral overuse. - Currency regime choice, from first principles — Mundell's 1961 OCA paper (added 2026-07) now sits alongside his 1963 capital-mobility paper, giving the base both halves of Mundell's own regime-choice framework: which geographic unit should share a currency (1961) and what a shared/fixed currency costs in terms of monetary independence (1963) — directly relevant to any EMU-style or dollarization-adjacent regime analysis. - Political economy of exchange rate policy — no longer a narrative-only gap after the addition of Frieden (1991), the canonical sectoral-interests paper. The base now has a genuine theoretical answer to "who wins and loses, domestically, from a given exchange-rate regime or level" — directly deepening the previously narrative-only Cortapasso et al. discussion of Brazilian political-currency dynamics.
A4: Exchange Rate | B4: Literature | C4: (whole area) | D4: Where the base is thin (single source, or gaps entirely) | E4: - Gaps not represented in the base at all (see the Qual - Exchange Rate tab for concrete candidate sources and priority order): - FX options and volatility — forwards, swaps, and futures are covered; option pricing, implied vol surfaces, and risk-reversal/skew as an FX positioning indicator are not. - China/RMB, or any large non-Brazil EM case study — the EM material in this base is almost entirely Brazil-specific; there's no equivalent depth for, say, RMB internationalization/managed float mechanics, or the "original sin" (EM local-currency debt market) literature. - Brazil-specific capital controls empirics (Chamon & Garcia's 2016 IOF-tax study) — the base now has the general institutional-view framework but not a dedicated empirical test on Brazil's own 2008-2012 episode; a natural next addition given the base's Brazil mandate. - The other two classic OCA papers (McKinnon 1963, Kenen 1969) — Mundell's OCA paper is now in the base, but the trio that forms the standard OCA canon isn't complete.
A5: Exchange Rate | B5: Literature | C5: (whole area) | D5: Which data backs which cluster (folded in 2026-09-10) | E5: Reading the map from the data side instead of the literature side gives three findings the cluster-by-cluster bullets don't show on their own: - Two data categories carry most of the base. Carry/rate differential (§2) and reserves/intervention (§6) each connect to four clusters — determination, valuation, crisis dynamics or regimes, and the practitioner layer. They are cited from the most distinct theoretical angles, so a defect in either propagates furthest. - One cluster connects to nothing: #policy_transmission (see the note in its own section). Eight of nine clusters have at least one series behind them; the ninth is the base's most political-economy-flavoured, and nothing in the pipeline measures it. - A single series usually needs more than one lens. Terms of trade (§3) and positioning (§8) each feed three clusters spanning both the academic literature and the Verde practitioner layer — a reminder that reading either through one theory at a time is a choice, not a default. And two gaps turn out to be the same gap seen from two sides, which is the argument for keeping the two layers in one file: FX options have neither a series (§8) nor a source (Garman-Kohlhagen), and non-Brazil EM depth has neither the REER peers (§7) nor the literature (Eichengreen & Hausmann). Closing one half of either would leave the other half still open.
A6: Exchange Rate | B6: Literature | C6: (whole area) | D6: One-paragraph overview (for board use) | E6: The exchange-rate bibliography covers the full standard arc of international-finance theory — from FX market mechanics and quoting conventions, through the interest-rate-parity/PPP family that links currencies to interest rates and inflation (now including the original UIP-failure econometrics, Fama 1984), to the two workhorse short-run models (Mundell-Fleming policy transmission and Dornbusch overshooting) and their long-run monetary counterparts — and grounds all of it in practitioner tools actually used to value currencies today (BEER, GSDEER, GSFEER) plus a now-comprehensive, multi-generational treatment of how currency crises build and break, spanning the field's original academic models (Krugman 1979, Flood & Garber, Obstfeld 1984) through both competing third-generation accounts of the Asian crisis (Krugman 2000, Chang & Velasco 1998). It also now covers currency-regime choice from first principles (Mundell's OCA theory), capital-flow management as an official policy doctrine (the IMF's institutional view and its empirical precursor), and the political economy of exchange-rate policy (Frieden's sectoral-interests framework). Its standout strengths are a genuinely deep, Brazil-specific thread on exchange-rate pass-through and BCB market operations, and an equally deep academic-theory-plus-case-study treatment of currency crisis dynamics and capital account policy. Its main remaining gaps are FX options/volatility and comparative EM depth beyond Brazil.
A7: Exchange Rate | B7: Literature | C7: #market_microstructure | D7: FX market structure, quoting, and plumbing
A8: Exchange Rate | B8: Literature | C8: #exchange_rate_determination | D8: nominal, real, and equilibrium exchange rates
A9: Exchange Rate | B9: Literature | C9: #currency_regimes | D9: regime choice, OCA theory, and the trilemma
A10: Exchange Rate | B10: Literature | C10: #balance_of_payments | D10: trade, capital flows, and the accounting identities | E10: No open gaps currently flagged for this cluster — the accounting-identity spine is well covered; deeper empirical BOP-crisis material sits under #currency_crisis_dynamics instead.
A11: Exchange Rate | B11: Literature | C11: #policy_transmission | D11: monetary & fiscal policy under different regimes, and its politics
A12: Exchange Rate | B12: Literature | C12: #applied_valuation_tools | D12: estimating the "equilibrium" exchange rate
A13: Exchange Rate | B13: Literature | C13: #capital_controls | D13: restrictions on capital flows as a policy tool
A14: Exchange Rate | B14: Literature | C14: #currency_crisis_dynamics | D14: how currency crises build and break
A15: Exchange Rate | B15: Literature | C15: #practitioner_mental_models | D15: how specific macro funds actually reason about BRL/USD | E15: Distinct in kind from clusters 1–8, not just in number. These are internally-authored syntheses of how specific macro funds actually reason about BRL/USD and the global dollar cycle, extracted from their own letters/notes rather than from published academic or institutional literature — a practitioner-reasoning cluster sitting alongside, not graded on the same foundational-score scale as, the literature above (hence the different table columns below).
A16: Exchange Rate | B16: Literature | C16: (whole area) | D16: 3. Optimal Currency Area (OCA) theory — absent entirely — PARTIALLY RESOLVED 2026-07 | E16: Only Mundell's 1963 capital-mobility paper was in the base; his more famous 1961 OCA paper was missing, along with the other two "classic" OCA criteria papers.
A17: Exchange Rate | B17: Literature | C17: (whole area) | D17: 4. FX options and volatility — absent entirely | E17: Forwards, swaps, and futures are covered (via CFA L1 and the BIS Triennial Survey figures); options pricing and volatility-based positioning indicators are not.
A18: Exchange Rate | B18: Literature | C18: (whole area) | D18: 6. Non-Brazil EM depth (RMB internationalization, "original sin") — almost entirely absent | E18: Every EM-specific source in the base is Brazil-focused. No equivalent depth for China/RMB or the broader EM local-currency-debt literature.
A19: Exchange Rate | B19: Literature | C19: (whole area) | D19: Suggested acquisition order | E19: 1. Chamon & Garcia (2016) (Section 2, Brazil angle) — a natural, low-effort next step given the base's Brazil mandate and the fact that the general capital-controls framework is now in place; this would be the direct empirical application to Brazil's own 2008-2012 IOF episode. 2. Garman & Kohlhagen (1983) (Section 4) — closes the one theory area (FX options/volatility) with no representation at all in the base. Everything else can follow based on what LIS's near-term research agenda actually needs (e.g., the remaining OCA companions only matter if EMU/monetary-union analysis is on the roadmap; RMB depth only matters if non-Brazil EM work is planned).
A20: Monetary Policy | B20: Literature | C20: (whole area) | D20: Scope | E20: Scope: technical literature only (papers, handbook chapters, selected textbook chapters). The Copom's own documents (comunicados, atas, RPM) are a separate track — §8 of the candidates file — already in obsidian/monetary_policy/clean_md/central_bank/, refreshed by the Copom ETL, and not listed here.
A21: Monetary Policy | B21: Literature | C21: (whole area) | D21: What the agent has to answer, and which clusters answer it | E21: The review that produced clusters 9-13 started from the agent's job rather than from the field's table of contents. The memo horizons are the next meeting, year-end, 1 year and 2-3 years (SISTEMA_AGENTES.md I.III), and the exchange-rate map already asks the agent for four outputs: Clusters 1-3 and 5 are the theoretical floor under all of these. Before 2026-10-07 the base was strong there and thin on every row of the table above; the Brazil cluster stopped in 2006.
A22: Monetary Policy | B22: Literature | C22: (whole area) | D22: Primary legal sources (institutional framework) | E22: Not literature, and therefore outside the clusters, but they define the target the reaction function responds to. Same treatment as the legal sources in the fiscal bibliography.
A23: Monetary Policy | B23: Literature | C23: (whole area) | D23: Deliberately out of this list | E23: - Woodford (2003) Interest and Prices, Cukierman (1992) and Bernanke, Laubach, Mishkin & Posen (1999) — the three books the candidates file used to carry. Their content for this agent is already covered: Woodford by Galí and Clarida-Galí-Gertler, Cukierman by Rogoff, Walsh and Barro-Gordon, Bernanke et al. by Svensson, Mishkin and the Brazil papers. Dropped 2026-10-07. - Phillips curve, expectation formation, fiscal theory of the price level, output-gap filters — owned by the inflation, fiscal and activity bibliographies. Expectations are not this agent's (SISTEMA_AGENTES.md I.III.xii); duplicating them here would blur the agents. </content>
A24: Monetary Policy | B24: Literature | C24: #policy_rules_and_credibility | D24: rules vs. discretion, time inconsistency, institutional design
A25: Monetary Policy | B25: Literature | C25: #new_keynesian_transmission | D25: the modern theoretical backbone
A26: Monetary Policy | B26: Literature | C26: #transmission_channels_financial_frictions | E26: Answers: How, and how fast, does the Selic reach activity and inflation in Brazil?
A27: Monetary Policy | B27: Literature | C27: #unconventional_policy_zlb | E27: Lowest processing priority of the base: Brazil came near the floor only in 2020.
A28: Monetary Policy | B28: Literature | C28: #global_spillovers_em_autonomy | E28: Answers: S4 — reaction function to a depreciation, and with which instrument
A29: Monetary Policy | B29: Literature | C29: #brazil_monetary_policy | E29: Answers: How, and how fast, does the Selic reach activity and inflation in Brazil? Answers: How restrictive is the Selic today? Answers: S2 — is a hike read as credibility or as validation of higher inflation? The 2006 cutoff is partly closed. The open gap this cluster carried — nothing after 2006 — is now covered on transmission (Minella & Souza-Sobrinho 2013, Bonomo & Martins 2016), the FX reaction (Kohlscheen 2014) and the BCB's model (SAMBA). Still uncovered by technical literature: the 2015-16 recession and the 2021-23 cycle. For those, the Copom's own documents (§8) and the technical boxes of the RPM — which come with the full RPM history, SISTEMA_AGENTES.md II.III.iv — are the primary source, not a paper still to be found.
A30: Monetary Policy | B30: Literature | C30: #reaction_function_and_gradualism | D30: estimating what the central bank responds to, and how fast | E30: Answers: S4 — reaction function to a depreciation, and with which instrument Answers: S1 — expected Selic path and balance of risks; how far it sits from the curve and from the Focus
A31: Monetary Policy | B31: Literature | C31: #policy_surprises_and_information_effect | D31: what a decision tells the market | E31: Answers: S2 — is a hike read as credibility or as validation of higher inflation?
A32: Monetary Policy | B32: Literature | C32: #communication_and_forward_guidance | E32: Answers: S3 — how the Copom described the exchange rate
A33: Monetary Policy | B33: Literature | C33: #neutral_rate | D33: how restrictive is the policy rate? | E33: Answers: How restrictive is the Selic today? Answers: S1 — expected Selic path and balance of risks; how far it sits from the curve and from the Focus
A34: Monetary Policy | B34: Literature | C34: #term_structure_and_market_pricing | D34: separating the expected path from the premium | E34: Answers: S1 — expected Selic path and balance of risks; how far it sits from the curve and from the Focus
A35: Monetary Policy | B35: Literature | C35: (whole area) | D35: Acquisition note | E35: The IMF blocks automated download. imf.org returns 403 to scripted requests (Akamai), for both the /external/pubs/ft/wp/ and the /-/media/ paths, from curl and from PowerShell alike (tested 2026-10-07). The papers themselves are free — open the link in a browser, save the PDF into repository/monetary_policy/raw_pdf/ with the suggested filename, and run /ingest monetary_policy. Third-party mirrors were not used.
A36: Monetary Policy | B36: Literature | C36: #brazil_policy_communication | D36: Copom primary sources | E36: A recurring institutional feed, not settled literature; no foundational score. The two decisions this section used to defer are taken: retention is the full history for comunicados (234) and atas (261), and the RPM for the last three years in full (12, Dec/2023 on); ingestion is the Copom ETL (pm_copom_projecoes.run(), code in domain/db/brasil/bcb/_copom_texto.py and _rpm_projecoes.py), writing straight into obsidian/monetary_policy/clean_md/central_bank/. Still pending: the full RPM history (SISTEMA_AGENTES.md II.III.iv).
A37: Economic Activity | B37: Literature | C37: (whole area) | D37: Scope | E37: Scope — deliberately excludes labor market theory. The user is considering splitting labor market into its own future agent, separate from economic activity. This file covers the business cycle and growth side only: what drives aggregate output up and down over the short run (business cycle theory), what drives it higher over the long run (growth theory), how "how much slack is there" gets measured (output gap/potential output), and how Brazil's own activity is tracked and dated. It deliberately does not cover search/matching models, the Beveridge curve, or NAIRU estimation — those stay reserved for the future labor market agent, even though output gap and NAIRU are close conceptual cousins. Scope boundary with the Qual - Monetary Policy tab: monetary policy's #new_keynesian_transmission and #transmission_channels_financial_frictions clusters already own the monetary transmission mechanism (Calvo pricing, the credit channel, the financial accelerator) — this file covers business cycles from the real/output side (RBC theory, growth theory) rather than how monetary policy transmits into them. Cluster 2 below (#modern_dsge_business_cycles) is the one place the two files sit closest together — Smets & Wouters (2007) and the CEE (2005) model are joint output-inflation-policy frameworks — included here because the lens is business-cycle propagation, not the policy-rule side already covered in monetary policy's bibliography. Scope boundary with the Qual - Inflation tab: Phillips curve theory and estimation (the use of the output gap as a slack measure) stays in the inflation file's cluster 1 — this file owns the theory and measurement of the output gap itself, which the inflation and monetary policy agents both already list as a Tier 2 dependency they need from a future activity agent. Scope boundary with exchange_rate_policy/ and inflation's cost-push cluster: commodity-price pass-through to consumer prices stays with inflation (cluster 3); this file's commodity cluster (8) covers the structural growth/Dutch-disease channel — how a commodity cycle reshapes potential output and industrial competitiveness — not the price-transmission channel.
A38: Economic Activity | B38: Literature | C38: (whole area) | D38: Suggested acquisition order | E38: 1. Okun (1962) and Cusinato, Minella & Pôrto Júnior (2010) — cheapest high-value pair: one closes the conceptual foundation for "output gap," the other is the single most load-bearing Brazil-specific reference, directly answering a gap already flagged in the monetary policy data inventory. 2. Solow (1956) and Kydland & Prescott (1982) — the two single most-cited papers in this entire bibliography; nothing else here makes full sense without these two frameworks (long-run growth, short-run real cycles) as background. 3. Banco Central do Brasil (2010, 2016, 2018) IBC-Br boxes — read together as a set; they're short, and the methodology only makes sense read as a sequence (launch → revision → comparison-to-GDP). 4. Corden & Neary (1982) — closes the Dutch disease gap cheaply; short, frequently invoked in Brazilian industrial-policy commentary, worth having early. 5. Solow (1957), Banco Central do Brasil (2018), Estudo Especial nº 27, and Veloso, Matos & Peruchetti (2020a/b) — the full productivity set; read the growth-accounting theory first, then BCB's labor-productivity-only application, then FGV/IBRE's fuller aggregate-TFP series, so the progression from theory → partial Brazilian application → complete Brazilian application is visible. 6. Duarte, Issler & Spacov (2004) — read alongside Burns & Mitchell and Stock & Watson (cluster 1/6) once those are acquired, since it's the direct Brazilian application of both. 7. Everything else, roughly in cluster order — the Barro & Sala-i-Martin (2004) textbook chapters, the IBGE national accounts methodology note, and the two 2019-2020 BCB Estudos Especiais (uncertainty, financial conditions) are lower urgency, useful thickening rather than foundational.
A39: Economic Activity | B39: Literature | C39: #business_cycle_theory_foundations | D39: the impulse-propagation framework and its two founding schools
A40: Economic Activity | B40: Literature | C40: #modern_dsge_business_cycles | D40: the medium-scale estimated models central banks actually run
...

Sheet Qual - Exchange Rate
A1: Name | B1: Autor/Company | C1: Date | D1: Importance (1-5) | E1: Do we have it? | F1: Type | G1: Cluster | H1: Why | I1: Comments | J1: File | K1: Ingestion | L1: Ingested on | M1: Extraction | N1: QC flags | O1: Synthesis | P1: Ingestion note
A2: Foreign Currency Option Values | B2: Garman, M. & Kohlhagen, S. | C2: 1983 | D2: 5 | E2: No | F2: Paper | G2: #market_microstructure | H2: The FX-adapted Black-Scholes model — the canonical closed-form FX option pricing formula. Fills the one theoretical area (options/volatility) with zero representation in the base, despite forwards, swaps and futures all being covered elsewhere.
A3: The Foreign Exchange Market (CFA L1) | B3: Barker, McNelis & Nickelsburg / CFA Institute | C3: 2025 | D3: 3 | E3: Yes | F3: CFA curriculum reading | G3: #market_microstructure | H3: Standard practitioner map of FX market plumbing: buy-side vs. sell-side structure, the swap/spot/forward turnover split (BIS Triennial Survey), quoting hierarchy, and the impossible trinity — the baseline reference underlying every other source's implicit assumptions about liquidity and quoting conventions. | J3: capital_flow_fx_market (CFA L1, 2025) | K3: Ingested | L3: 2026-10-20 | M3: reclean (cleaner change) | O3: Yes
A4: Exchange Rate Calculations (CFA L1) | B4: CFA Institute | C4: 2025 | D4: 3 | E4: Yes | F4: CFA curriculum reading | G4: #market_microstructure | H4: The calculation toolkit — cross-rate/triangular-arbitrage mechanics, forward points, and covered interest rate parity (CIP) as a no-arbitrage identity — that the entire parity-conditions cluster (UIP, real interest parity) is built on top of. | J4: exchange_rate_calculation (CFA L1, 2025) | K4: Ingested | L4: 2026-10-20 | M4: reclean (cleaner change) | O4: Yes
A5: Posicao de Cambio, Saldo Cambial, Disponibilidade Cambial e Exposicao Cambial | B5: Banco Central do Brasil | C5: 2020 | D5: 4 | E5: Yes | F5: Central bank technical note | G5: #market_microstructure | H5: The BCB's own precise disambiguation of four related-but-distinct FX plumbing concepts (position, flow, availability, exposure) plus its concrete intervention toolkit (spot auctions vs. repo-style line auctions vs. FX swaps), illustrated with a real 2019 case cushioning a projected US$70bn short position down to US$34bn. Essential ground truth for reading any BCB-published FX market data. | J5: posicao_de_cambio (BCB, 2020) | K5: Ingested | L5: 2026-10-20 | M5: reclean (cleaner change)
A6: Currency options / risk reversals primer (source TBD) | B6: CFA curriculum or bank research | C6: TBD | D6: 2 | E6: No | F6: Paper / practitioner note | G6: #market_microstructure | H6: Placeholder for a positioning-and-skew-as-signal companion to Garman-Kohlhagen's pricing model, ideally at the same practitioner register as the existing CFA/Goldman sources — would close the "options as an FX sentiment/positioning indicator" half of the gap.
A7: Expectations and Exchange Rate Dynamics | B7: Dornbusch, R. | C7: 1976 | D7: 5 | E7: Yes | F7: Paper | G7: #exchange_rate_determination | H7: The founding overshooting model — sticky goods prices plus instantaneously-clearing asset markets mean a permanent monetary shock makes the exchange rate depreciate more than its long-run equilibrium level before appreciating back as prices catch up. The single most-cited explanation for why FX volatility so badly outpaces relative-price-level volatility. | J7: expectations_and_exchange_rate_dynamics (Dornbusch, 1976) | K7: Ingested | L7: 2026-10-20 | M7: reclean (cleaner change) | O7: Yes
A8: Forward and Spot Exchange Rates | B8: Fama, E. | C8: 1984 | D8: 5 | E8: Yes | F8: Paper | G8: #exchange_rate_determination | H8: The original "wrong-signed beta" UIP-failure econometrics — the single most-cited empirical fact behind the forward-premium/carry-trade puzzle. Shows most of the variance in the forward-spot differential is risk-premium variance, not genuine forecast information, and catalogs the competing explanations (irrationality, official "leaning against the wind," the peso problem, Fama-Gibbons/Mundell-Tobin real-rate effects) the field still adjudicates between four decades later. | J8: forward_spot_exchange (Fama, 1984) | K8: Ingested | L8: 2026-10-20 | M8: reclean (cleaner change)
A9: Anomalies: Foreign Exchange | B9: Froot, K. & Thaler, R. | C9: 1990 | D9: 4 | E9: Yes | F9: Paper (survey) | G9: #exchange_rate_determination | H9: Accessible, non-technical survey of the forward premium puzzle — good complement if you want context/synthesis alongside the raw econometrics | I9: Acquisition priority: Low (survey, optional) Suggested file: fx_anomalies_survey (Froot & Thaler, 1990).pdf | J9: fx_anomalies_survey (Froot & Thaler, 1990) | K9: Ingested | L9: 2026-10-20 | M9: reclean (cleaner change)
A10: International Economics, Ch. 14 - Exchange Rates and the Foreign Exchange Market | B10: Krugman, Obstfeld & Melitz | C10: 2023 | D10: 4 | E10: Yes | F10: Textbook chapter | G10: #exchange_rate_determination | H10: The standard textbook formalization of UIP as the FX market's core equilibrium condition, and the asset-approach reframing of exchange rates as forward-looking asset prices rather than goods prices — the spine the whole determination cluster organizes around. | J10: exchange_rate_foreign_exchange_market (Krugman, 2023) | K10: Ingested | L10: 2026-10-20 | M10: reclean (cleaner change) | O10: Yes
A11: International Economics, Ch. 15 - Money, Interest Rates, and Exchange Rates | B11: Krugman, Obstfeld & Melitz | C11: 2023 | D11: 4 | E11: Yes | F11: Textbook chapter | G11: #exchange_rate_determination | H11: Textbook derivation of Dornbusch overshooting via the money-market/interest-parity diagram, the long-run-monetary-neutrality "currency reform" intuition, and Latin American money-growth/inflation scatter evidence (1980–2014) grounding the quantity-theory logic empirically. | J11: money_interest_rate_exchange_rates (Krugman, 2023) | K11: Ingested | L11: 2026-10-20 | M11: reclean (cleaner change) | O11: Yes
A12: International Economics, Ch. 16 - Price Levels and the Exchange Rate in the Long Run | B12: Krugman, Obstfeld & Melitz | C12: 2023 | D12: 4 | E12: Yes | F12: Textbook chapter | G12: #exchange_rate_determination | H12: Long-run PPP/monetary-approach chapter — derives real interest rate parity as an accounting identity (not an empirical requirement), formalizes the Balassa-Samuelson effect behind BEER-style models, and reports Frankel & Rose's ~4-year PPP-deviation half-life, independently corroborating GSDEER's convergence-speed estimate. | J12: price_levels_exchange_rate_lr (Krugman, 2023) | K12: Ingested | L12: 2026-10-20 | M12: reclean (cleaner change) | O12: Yes
A13: Currency Exchange Rates: Understanding Equilibrium Value (CFA L2) | B13: CFA Institute | C13: 2025 | D13: 4 | E13: Yes | F13: CFA curriculum reading | G13: #exchange_rate_determination | H13: The densest single synthesizing source in the base (78pp) — ties UIP, CIP, ex ante PPP, real interest parity and the international Fisher effect into one master parity-conditions diagram, and is the direct source of the carry-trade return-distribution mechanics (fat tails, negative skew) used throughout the base. | J13: exchange_rate_understanding_equilibrium (CFA L2, 2025) | K13: Ingested | L13: 2026-10-20 | M13: reclean (cleaner change) | O13: Yes
A14: A Theory of Optimum Currency Areas | B14: Mundell, R.A. | C14: 1961 | D14: 5 | E14: Yes | F14: Paper | G14: #currency_regimes | H14: The founding OCA paper — defines the optimal domain for a shared currency as the region with high internal and low external factor mobility, not any particular political border. Directly prefigures the euro debate three decades early via the Meade-Scitovsky exchange cited in the paper. | J14: theory_optimum_currency_areas (Mundell, 1961) | K14: Ingested | L14: 2026-10-20 | M14: reclean (cleaner change)
A15: Capital Mobility and Stabilization Policy Under Fixed and Flexible Exchange Rates | B15: Mundell, R.A. | C15: 1963 | D15: 5 | E15: Yes | F15: Paper | G15: #currency_regimes | H15: The founding Mundell-Fleming result — under perfect capital mobility, monetary policy is powerful under floating rates and impotent under fixed rates, and fiscal policy is the mirror image. The paper the impossible trinity and every fixed-vs-floating policy-effectiveness argument in the base ultimately traces back to. | J15: capital_mobility_exchange_rates_regimes (Mundell, 1963) | K15: Ingested | L15: 2026-10-20 | M15: reclean (cleaner change) | O15: Yes
A16: Optimum Currency Areas | B16: McKinnon, R. | C16: 1963 | D16: 5 | E16: No | F16: Paper | G16: #currency_regimes | H16: The second classic OCA criterion (economic openness) — the standard complement to Mundell (1961); together with Kenen (1969), completes the canonical Mundell/McKinnon/Kenen OCA trio still taught as the field's baseline.
A17: The Theory of Optimum Currency Areas: An Eclectic View | B17: Kenen, P. | C17: 1969 | D17: 5 | E17: No | F17: Paper | G17: #currency_regimes | H17: The third classic OCA criterion (production diversification as a buffer against asymmetric shocks) — closes the canonical OCA trio alongside Mundell (1961) and McKinnon (1963).
A18: Exchange Rates and Financial Fragility (NBER WP 7418) | B18: Eichengreen, B. & Hausmann, R. | C18: 1999 | D18: 5 | E18: Yes | F18: Paper | G18: #currency_regimes | H18: The paper that coined "original sin" — EM inability to borrow abroad in local currency, and how that shapes exchange-rate-regime choice | I18: Acquisition priority: High Suggested file: original_sin_em_debt (Eichengreen & Hausmann, 1999).pdf Also feeds #currency_crisis_dynamics | J18: original_sin_em_debt (Eichengreen & Hausmann, 1999) | K18: Ingested | L18: 2026-10-20 | M18: reclean (cleaner change)
A19: International Economics, Ch. 18 - Fixed Exchange Rates and Foreign Exchange Intervention | B19: Krugman, Obstfeld & Melitz | C19: 2023 | D19: 4 | E19: Yes | F19: Textbook chapter | G19: #currency_regimes | H19: The textbook mechanics of defending a peg — central bank balance-sheet mechanics, sterilized vs. non-sterilized intervention, the risk-premium channel under imperfect asset substitutability, and the reserve-currency asymmetry that let the US never have to intervene under Bretton Woods. | J19: fixed_exchange_rate_intervention (Krugman, 2023) | K19: Ingested | L19: 2026-10-20 | M19: reclean (cleaner change) | O19: Yes
A20: Renminbi Internationalization: Achievements, Prospects, and Challenges | B20: Eichengreen, B. & Kawai, M. | C20: 2014 | D20: 3 | E20: Yes | F20: Paper | G20: #currency_regimes | H20: Gives a concrete non-Brazil EM case study — RMB internationalization and managed-float mechanics, a natural parallel to the BCB posicao_de_cambio piece already in the base | I20: Acquisition priority: Medium Suggested file: rmb_internationalization (Eichengreen & Kawai, 2014).pdf Also feeds #market_microstructure | J20: rmb_internationalization (Eichengreen & Kawai, 2014) | K20: Ingested | L20: 2026-10-20 | M20: reclean (cleaner change)
A21: International Economics, Ch. 13 - National Income Accounting and the Balance of Payments | B21: Krugman, Obstfeld & Melitz | C21: 2023 | D21: 4 | E21: Yes | F21: Textbook chapter | G21: #balance_of_payments | H21: The accounting-identity backbone of the whole balance-of-payments cluster — X−M = (S−I)+(T−G), the twin-deficits decomposition, and the BPM6 current/capital/financial account structure that later sources (Paiva's BEER, the GSFEER current-account-gap model) build directly on top of. | J21: national_income_balance_payments (Krugman, 2023) | K21: Ingested | L21: 2026-10-20 | M21: reclean (cleaner change)
A22: Invested Interests: The Politics of National Economic Policies in a World of Global Finance | B22: Frieden, J. | C22: 1991 | D22: 5 | E22: Yes | F22: Paper | G22: #policy_transmission | H22: The canonical political-economy-of-exchange-rates paper — maps which domestic sectors (import-competing tradables, export tradables, nontradables, international investors) favor currency stability vs. policy autonomy, and a weak vs. strong currency. Gives a formal "who wins, who loses" mechanism behind any specific country's currency-regime politics, including Brazil's own. | J22: invested_interest (Frieden, 1991) | K22: Ingested | L22: 2026-10-20 | M22: reclean (cleaner change)
A23: International Economics, Ch. 17 - Output and the Exchange Rate in the Short Run | B23: Krugman, Obstfeld & Melitz | C23: 2023 | D23: 4 | E23: Yes | F23: Textbook chapter | G23: #policy_transmission | H23: The DD-AA model plus the Marshall-Lerner condition and the J-curve — the formal elasticity conditions under which a depreciation actually improves (rather than worsens) the trade balance, and the mechanism by which a weak short-run J-curve response amplifies Dornbusch overshooting. | J23: output_exchange_rates_sr (Krugman, 2023) | K23: Ingested | L23: 2026-10-20 | M23: reclean (cleaner change) | O23: Yes
A24: The Political Economy of International Monetary Relations | B24: Broz, J.L. & Frieden, J. | C24: 2001 | D24: 3 | E24: Yes | F24: Paper (survey) | G24: #policy_transmission | H24: A single-source field survey of exchange-rate political economy — useful as a broader, updated overview alongside Frieden's original 1991 sectoral-interests paper. | J24: political_economy_international_monetary_relations (Broz & Frieden, 2001) | K24: Ingested | L24: 2026-10-20 | M24: reclean (cleaner change)
A25: External Adjustment and Equilibrium Exchange Rate in Brazil (IMF WP/06/221) | B25: Paiva, C. | C25: 2006 | D25: 4 | E25: Yes | F25: Paper | G25: #applied_valuation_tools | H25: Applies the BEER (Behavioral Equilibrium Exchange Rate) methodology to Brazil via Johansen cointegration — finds the real's 2003–05 appreciation was largely an equilibrium phenomenon (net foreign asset position + terms of trade), a direct empirical counterpoint to reading any large REER move as automatic misalignment. | J25: equilibrium_exchange_brazil (Paiva, 2006) | K25: Ingested | L25: 2026-10-20 | M25: reclean (cleaner change) | O25: Yes
A26: GSDEER - A User's Guide | B26: Bhushan & Cahill, Goldman Sachs | C26: 2023 | D26: 3 | E26: Yes | F26: Practitioner research note | G26: #applied_valuation_tools | H26: Goldman's own methodology note for its Dynamic Equilibrium Exchange Rate model (PPP adjusted for terms of trade and productivity) — documents which component actually drives fair value by currency (inflation for EUR/GBP/CAD, terms of trade for commodity exporters) and the empirical convergence timeline (~3 years to beat a random walk, ~5 years to fully converge, ~20%/year closure rate). | J26: gsdeer_manual_guide (Goldman, 2023) | K26: Ingested | L26: 2026-10-20 | M26: reclean (cleaner change) | O26: Yes
A27: Primer: GSDEER and GSFEER | B27: Alves & Jenkins, Goldman Sachs | C27: 2025 | D27: 3 | E27: Yes | F27: Practitioner research note | G27: #applied_valuation_tools | H27: Introduces GSFEER (the macro-balance-approach cousin to GSDEER, based on the current-account gap vs. its savings/investment "norm") and Goldman's own model-blending weights by horizon. Flags that GSDEER and GSFEER currently give directionally different fair-value signals for BRL specifically, concluding carry and terms-of-trade dominate BRL price action over either anchor. | J27: primer_gsdeer_gsfeer (Goldman, 2025) | K27: Ingested | L27: 2026-10-20 | M27: reclean (cleaner change) | O27: Yes
A28: Capital Inflows: The Role of Controls (IMF SPN/10/04) | B28: Ostry, Ghosh, Habermeier, Chamon, Qureshi & Reinhardt | C28: 2010 | D28: 4 | E28: Yes | F28: Paper | G28: #capital_controls | H28: The empirical/pragmatic precursor to the IMF's later institutional view — lays out a policy decision sequence (let the currency appreciate → accumulate reserves → sterilize → adjust monetary/fiscal policy → controls as last resort) and a four-condition test for when inflow controls are justified. Finds controls have little robust effect on aggregate inflow volume or appreciation, but real, demonstrable effects on the maturity composition of external liabilities. | J28: capital_inflow (IMF, 2010) | K28: Ingested | L28: 2026-10-20 | M28: reclean (cleaner change)
A29: The Liberalization and Management of Capital Flows: An Institutional View | B29: IMF Staff (Arora, Habermeier, Ostry, Weeks-Brown et al.) | C29: 2012 | D29: 5 | E29: Yes | F29: Official institutional doctrine | G29: #capital_controls | H29: The IMF's own standing official doctrine on capital account liberalization and management — introduces the CFM/MPM terminology distinction, a liberalization sequencing framework ("long before short, FDI before debt, inflows before outflows"), and explicit design criteria (transparent, targeted, temporary, non-discriminatory) for when new controls are appropriate. The single most citable "what does official policy actually say" reference in this cluster. | J29: the_liberalization_management_capital_flows (IMF, 2012) | K29: Ingested | L29: 2026-10-20 | M29: reclean (cleaner change)
A30: Capital Controls in Brazil: Effective? | B30: Chamon, M. & Garcia, M. | C30: 2016 | D30: 4 | E30: Yes | F30: Paper | G30: #capital_controls | H30: Direct empirical test of Brazil's own 2008–2012 IOF-tax episode — the natural Brazil-specific complement the general capital-controls framework above is missing, and the base's most direct empirical evidence on whether Brazil's own use of the tool actually worked. | J30: capital_controls_brazil (Chamon & Garcia, 2016) | K30: Ingested | L30: 2026-10-20 | M30: reclean (cleaner change)
A31: Modelos Mentais de Cambio - Verde Asset Management (2020-2026) | B31: Verde Asset Management (internal synthesis) | C31: 2020-2026 | E31: Yes | F31: Practitioner mental model | G31: #practitioner_mental_models | H31: Consolidated from 73 monthly letters (Jan/2020–May/2026), 507 identified mental-model instances, organized into 5 clusters (Brazil fiscal/credit/institutions; external fundamentals/commodities; carry & rate differentials; global dollar cycle & the Fed; flows/positioning/risk appetite), each with dated, quoted real-world applications. | I31: Mental-model synthesis status: Done
A32: Kinea Insights - mental-model synthesis | B32: Kinea Investimentos (internal synthesis, pending) | C32: 2021-2026 | E32: Yes | F32: Practitioner mental model | G32: #practitioner_mental_models | H32: 60 "Carta do Gestor" letters (repository/mental_model/kinea/) plus the 64 Kinea Insights notes (repository/mental_model/kinea_insights/). | I32: Mental-model synthesis status: Done
A33: Modelos Mentais de Câmbio — Kapitalo | B33: Kapitalo | E33: Yes | F33: Practitioner mental model | G33: #practitioner_mental_models | H33: 83 K10 letters, Jul/2019–Mai/2026 (repository/mental_model/kapitalo/). | I33: Mental-model synthesis status: Done
A34: Goldman Sachs Global FX Trader | B34: Goldman Sachs Global FX Trader | E34: Partial | F34: Practitioner mental model | G34: #practitioner_mental_models | H34: First 25 of ~80 weekly issues processed (repository/mental_model/goldman_sachs/). | I34: Mental-model synthesis status: Partial
A35: SPX Capital | B35: SPX Capital | E35: No | F35: Practitioner mental model | G35: #practitioner_mental_models | H35: 7 PDFs in repository/mental_model/spx_capital/, not reviewed. | I35: Mental-model synthesis status: Not built
A36: A Model of Balance-of-Payments Crises | B36: Krugman, P. | C36: 1979 | D36: 5 | E36: Yes | F36: Paper | G36: #currency_crisis_dynamics | H36: The founding first-generation crisis model - rational speculators attack before reserves would have run out anyway. | J36: balance_of_payment_crisis (Krugman, 1979) | K36: Ingested | L36: 2026-10-20 | M36: reclean (cleaner change)
A37: Collapsing Exchange-Rate Regimes: Some Linear Examples | B37: Flood, R.P. & Garber, P.M. | C37: 1983 | D37: 4 | E37: Yes | F37: Paper | G37: #currency_crisis_dynamics | H37: Standard linear, closed-form companion to Krugman (1979) - introduces the 'shadow exchange rate' technique for solving collapse timing. | J37: collapsing_exchange_rate_regimes (Flood, 1983) | K37: Ingested | L37: 2026-10-20 | M37: reclean (cleaner change)
A38: Balance-of-Payments Crises and Devaluation (NBER WP 1486) | B38: Obstfeld, M. | C38: 1984 | D38: 5 | E38: Yes | F38: Paper | G38: #currency_crisis_dynamics | H38: The original second-generation, self-fulfilling crisis model - working-paper precursor to Obstfeld's canonical 1986 AER piece. | J38: rational_self_fulfilling_bpc (Obstfeld, 1984) | K38: Ingested | L38: 2026-10-20 | M38: reclean (cleaner change)
A39: The Logic of Currency Crises (NBER WP 4640) | B39: Obstfeld, M. | C39: 1994 | D39: 3 | E39: Yes | F39: Paper (survey) | G39: #currency_crisis_dynamics | H39: Accessible single-source synthesis bridging first- and second-generation crisis logic. | J39: logic_currency_crises (Obstfeld, 1994) | K39: Ingested | L39: 2026-10-20 | M39: reclean (cleaner change)
A40: Financial Crises in Emerging Markets: A Canonical Model | B40: Chang, R. & Velasco, A. | C40: 1998 | D40: 5 | E40: Yes | F40: Paper | G40: #currency_crisis_dynamics | H40: One of two competing third-generation models of the 1997-98 Asian crisis - open-economy Diamond-Dybvig bank-run model. | J40: financial_crises_emerging_markets (Chang, 1998) | K40: Ingested | L40: 2026-10-20 | M40: reclean (cleaner change)
...

Sheet Quant - Exchange Rate
A1: Name | B1: Source | C1: Date | D1: Importance | E1: Do we have it? | F1: Category | G1: Comments
A2: PTAX sell (spot) | B2: macro_brasil.cmb_ptax · ptax_venda (SGS 1) | C2: 1994-07-01 → today, daily (Real Plan implementation — pre-Real data in extinct currencies excluded) | E2: Yes | F2: 1. Spot price
A3: Interbank FX volume, T+1/T+2 settlement | B3: macro_brasil.cmb_ptax · fx_interbank_vol_t1 (SGS 20359), fx_interbank_vol_t2 (SGS 20205) | C3: 1994-07-04 → today, daily | E3: Yes | F3: 1. Spot price
A4: Selic (raw) | B4: macro_international.diferenciais_juros · selic | C4: 1999-03 → today (SGS 432 has no earlier data) | E4: Yes | F4: 2. Interest rate differential (carry)
A5: Fed Funds (raw) | B5: macro_international.diferenciais_juros · fed_funds | C5: 1995 → today | E5: Yes | F5: 2. Interest rate differential (carry)
A6: Nominal ex-post differential | B6: macro_international.diferenciais_juros · diferencial_nominal | C6: 1999-03 → today | E6: Yes | F6: 2. Interest rate differential (carry)
A7: Real ex-post differential (Selic − IPCA vs. Fed Funds − CPI) | B7: macro_international.diferenciais_juros · real_br_ex_post, real_us_ex_post, diferencial_real | C7: 1999-03 → today | E7: Yes | F7: 2. Interest rate differential (carry)
A8: Terms of trade index (PX/PM, base 2018=100) | B8: macro_brasil.cmb_termos_troca · termos_de_troca_funcex (IPEADATA FUNCEX12_TTR12) | E8: Yes | F8: 3. Terms of trade / commodity prices | G8: 1978 → today, monthly
A9: Current account, trade balance+services, goods exports | B9: macro_brasil.cmb_balanco_pagmt · conta_corrente, balanca_comercial_servicos, exportacao_bens | C9: 2001 → today | E9: Yes | F9: 4. Balance of payments
A10: Financial account, FDI (net and inflows), outward FDI | B10: macro_brasil.cmb_balanco_pagmt · conta_financeira, investimento_direto_liquido, idp_ingressos, ide_saidas | C10: 2001 → today | E10: Yes | F10: 4. Balance of payments
A11: Portfolio investment (total, equities, fixed income) | B11: macro_brasil.cmb_balanco_pagmt · investimento_carteira, carteira_acoes, carteira_renda_fixa | C11: 2001 → today | E11: Yes | F11: 4. Balance of payments
A12: Total balance/inflow/outflow | B12: macro_brasil.cmb_fluxo_cambial · total_saldo, total_entrada, total_saida | E12: Yes | F12: 5a. Registered FX flow (BCB Nota Cambial)
A13: Commercial sector (inflow/outflow) | B13: macro_brasil.cmb_fluxo_cambial · comercial_entrada, comercial_saida | E13: Yes | F13: 5a. Registered FX flow (BCB Nota Cambial)
A14: Financial sector (balance) | B14: macro_brasil.cmb_fluxo_cambial · financeiro_saldo | E14: Yes | F14: 5a. Registered FX flow (BCB Nota Cambial)
A15: Daily — total balance, exports (total/ACC/PA/other), imports, commercial balance, financial purchases/sales/balance | B15: macro_brasil.cmb_cambio_contratado · cc_saldo_total, cc_export_*, cc_import_total, cc_saldo_comercial, cc_fin_compras, cc_fin_vendas, cc_fin_saldo | E15: Yes | F15: 5b. Contracted FX (bank-client movement)
A16: Monthly — detailed financial breakdown (services, income, domestic/foreign capital) | B16: macro_brasil.cmb_cambio_contratado · cc_fin_saldo_det, cc_fin_servicos, cc_fin_rendas, cc_fin_cap_bras, cc_fin_cap_ext | E16: Yes | F16: 5b. Contracted FX (bank-client movement)
A17: Total reserves and by component (FX securities, deposits, IMF, SDR, gold, other assets) | B17: macro_brasil.cmb_reservas_bc | C17: monthly | E17: Yes | F17: 6. International reserves and BCB intervention
A18: Reserves — total and liquidity concept | B18: macro_brasil.cmb_reservas_bc | C18: daily | E18: Yes | F18: 6. International reserves and BCB intervention
A19: Banks' net FX spot position | B19: macro_brasil.cmb_reservas_bc | C19: monthly | E19: Yes | F19: 6. International reserves and BCB intervention
A20: BCB FX swap — net position | B20: macro_brasil.cmb_reservas_bc | C20: monthly | E20: Yes | F20: 6. International reserves and BCB intervention
A21: Stock of repo lines/loans/repurchase agreements in FX | B21: macro_brasil.cmb_reservas_bc | C21: monthly | E21: Yes | F21: 6. International reserves and BCB intervention
A22: BCB interventions (spot, forwards, FX loans/repos, repo lines) — only days with actual intervention | B22: macro_brasil.cmb_reservas_bc | C22: daily (sparse) | E22: Yes | F22: 6. International reserves and BCB intervention
A23: Real (broad) and nominal (broad) REER — Brazil, Mexico, Chile, Colombia | B23: macro_international.cmb_reer | C23: 1994 → today (BIS, full history) | E23: Yes | F23: 7. Real effective exchange rate (REER)
A24: Open interest, net/long/short positioning of "leveraged money" and non-reportables | B24: macro_international.cmb_cot_fx · open_interest, lev_long, lev_short, lev_net, nonrept_long, nonrept_short | C24: BRL and MXN, weekly (Tuesdays), 2010 → today | E24: Yes | F24: 8. Speculative positioning (FX futures)
A25: IPCA (28 series, incl. cores) | B25: macro_brasil.inflc_agregados | E25: Yes | F25: 9. Inflation differential and market expectations | G25: 1980 → today
A26: Focus expectations — IPCA 12m/24m, IGP-M, Selic | B26: macro_brasil.expc_focus | E26: Yes | F26: 9. Inflation differential and market expectations | G26: 2001 → today Mr. Paulo suggestion
A27: US CPI (via FRED, consumed inside the differentials calculation) | B27: macro_international.diferenciais_juros (cpi_12m_us) | E27: Yes | F27: 9. Inflation differential and market expectations | G27: ~36m rolling
A28: Ex-ante interest rate differentials (Focus × Fed Funds futures/OIS) | D28: High | E28: No | F28: 2. Interest rate differential (carry) | G28: Ex-ante differentials (based on expectations, not realized inflation) not implemented yet — see the pending item in analytics/brasil/exchange_rate/CLAUDE.md, uses macro_brasil.expc_focus (Focus) on the BR side and FRED (FF{m} futures/OIS, MICH/T5YIE) on the US side.
A29: CEP/CBE granularity of the financial FX flow | D29: Medium | E29: No | F29: 5a. Registered FX flow (BCB Nota Cambial) | G29: Script: domain/db/brasil/bcb/cmb_fluxo_cambial.py. Coverage: 2003 → today. Gaps: CEP/CBE sub-items of the financial flow (finer granularity, published in the weekly Nota Cambial) — candidate SGS codes (24372–24376) unconfirmed. Commercial balance (24366) timed out during research — can be derived as comercial_entrada − comercial_saida if needed.
A30: Wire cmb_ptax into the analysis agent's snapshot (agent_data.py) | D30: Medium | E30: No | F30: 1. Spot price | G30: Why it matters: the dependent variable — every other category in this inventory exists to explain moves in this one series. Script: domain/db/brasil/bcb/cmb_ptax.py. Daily series — historical load chunks by year (BCB API rejects windows > 10 years for daily series, confirmed via 406 response). Remaining gap: the analysis agent (analytics/brasil/exchange_rate/agent_data.py) hasn't been updated yet to pull cmb_ptax into its snapshot — the data exists but isn't wired into the agent's output.
A31: Cupom cambial + B3 futures (requires Bloomberg access) | D31: Low | E31: No | F31: 2. Interest rate differential (carry) | G31: Cupom cambial (DDI/FRC curve) and B3 futures (DOL/WDO) — deferred, requires Bloomberg access (blpapi/xbbg).
A32: REER/COT for EM peers beyond BR/MX/CL/CO | D32: Low | E32: No | F32: 7. Real effective exchange rate (REER) | G32: Only 4 LatAm countries (BR/MX/CL/CO) — no coverage of other relevant EM peers for comparison (e.g., Turkey, South Africa, India) or developed-market peers.
A33: Options-based positioning data (skew, risk reversal) | D33: Low | E33: No | F33: 8. Speculative positioning (FX futures) | G33: No options-based positioning data (skew, risk reversal) — see the corresponding gap in the bibliography (exchange_rate_bibliography_gaps.md, section 4, FX options and volatility).
A34: Persistent macro_us schema (today only ad hoc FRED in the oráculo) | D34: Low | E34: No | F34: 10. Domestic activity backdrop (context, not FX-specific) | G34: Not an FX category, kept as context. The presentation-layer copy merged in here dropped this section outright, on the grounds that it is general macro backdrop rather than FX-specific data — a fair call for a reading audience, but the series are worth keeping listed for the agent. General macro_brasil series that help contextualize the domestic cycle (relevant for carry/country risk, but not "FX data" per se): atv_ibcbr (monthly GDP proxy), atv_pib, atv_pim (industrial production), atv_pmc/atv_pms (retail/services), mt_pnad (labor market), mt_caged, cred_credito_amplo, cred_credito_familias. Full table in CLAUDE.md. On the US side, activity/inflation data today only exists ad hoc inside analytics/oraculo/us/term_us.py (via FRED) — there's no persistent macro_us schema equivalent to macro_brasil (already logged as a pending item in CLAUDE.md, "Média prioridade — US expandir dados").
A35: No individual commodity prices (iron ore, soybeans, oil) | E35: No | F35: 3. Terms of trade / commodity prices | G35: No individual commodity prices (iron ore, soybeans, oil) — only the aggregate Funcex index. If the agent needs to decompose terms of trade by commodity, there's no data for that today.
A36: real_narrow was excluded from scope (broad basket only). | E36: No | F36: 7. Real effective exchange rate (REER) | G36: real_narrow was excluded from scope (broad basket only).
A37: CLP and COP have no CME futures | E37: No | F37: 8. Speculative positioning (FX futures) | G37: CLP and COP have no CME futures — they don't appear in the TFF report, and there's no equivalent alternative data today.
A38: History not available before 2010 (CFTC returns 404 for 2006–2009). | E38: No | F38: 8. Speculative positioning (FX futures) | G38: History not available before 2010 (CFTC returns 404 for 2006–2009).

Sheet Qual - Monetary Policy
A1: Name | B1: Autor/Company | C1: Date | D1: Importance (1-5) | E1: Do we have it? | F1: Type | G1: Cluster | H1: Why | I1: Comments | J1: File | K1: Ingestion | L1: Ingested on | M1: Extraction | N1: QC flags | O1: Synthesis | P1: Ingestion note
A2: The Role of Monetary Policy | B2: Friedman, M. | C2: 1968 | D2: 5 | E2: Yes | F2: Paper | G2: #policy_rules_and_credibility | H2: Natural rate; what monetary policy can and cannot do | J2: the_role_monetary_policy (Friedman, 1968) | K2: Ingested | L2: 2026-10-20 | M2: reclean (cleaner change) | O2: Yes
A3: Rules Rather than Discretion: The Inconsistency of Optimal Plans | B3: Kydland, F. & Prescott, E. | C3: 1977 | D3: 5 | E3: Yes | F3: Paper | G3: #policy_rules_and_credibility | H3: Time inconsistency: discretion produces inflation bias | J3: time_inconsistency_optimal_plans (Kydland & Prescott, 1977) | K3: Ingested | L3: 2026-10-20 | M3: reclean (cleaner change) | O3: Yes
A4: A Positive Theory of Monetary Policy in a Natural Rate Model | B4: Barro, R. & Gordon, D. | C4: 1983 | D4: 5 | E4: Yes | F4: Paper | G4: #policy_rules_and_credibility | H4: The workhorse inflation-bias model | J4: positive_theory_monetary_policy (Barro & Gordon, 1983) | K4: Ingested | L4: 2026-10-19 | M4: reclean (cleaner change) | O4: Yes
A5: The Optimal Degree of Commitment to an Intermediate Monetary Target | B5: Rogoff, K. | C5: 1985 | D5: 5 | E5: Yes | F5: Paper | G5: #policy_rules_and_credibility | H5: The conservative central banker | I5: PDF acquired (JSTOR copy). | J5: optimal_commitment_intermediate_target (Rogoff, 1985) | K5: Ingested | L5: 2026-10-20 | M5: reclean (cleaner change) | O5: Yes
